INFO:Dataset_totali:{'SVC': 0.6667480667480667, 'DT': 0.597964997964998, 'NB': 0.706064306064306, 'LD': 0.7192104192104192, 'MLP': 0.7037851037851038}
ERROR:root:Internal Python error in the inspect module.
Below is the traceback from this internal error.

INFO:root:
Unfortunately, your original traceback can not be constructed.

INFO:Dataset_totali:{'SVC': 0.6667480667480667, 'DT': 0.5603174603174603, 'RF': 0.6229141229141228, 'NB': 0.706064306064306, 'LD': 0.7192104192104192, 'MLP': 0.6741554741554742}
INFO:Dataset_totali:{'SVC': 0.6667480667480667, 'DT': 0.5682539682539682, 'RF': 0.5927553927553928, 'NB': 0.69010989010989, 'LD': 0.7049247049247049, 'MLP': 0.6667480667480667}
INFO:Dataset_totali:{'SVC': 0.7715913715913716, 'DT': 0.608017908017908, 'RF': 0.631013431013431, 'NB': 0.7271469271469271, 'LD': 0.7180708180708181, 'MLP': 0.7271469271469271}
INFO:Dataset_totali:{'SVC': 0.7579161579161579, 'DT': 0.6376475376475377, 'RF': 0.6446072446072447, 'NB': 0.7493691493691493, 'LD': 0.7118030118030119, 'MLP': 0.7266178266178266}
